{"uuid": "67bf4050-831d-4d87-8a84-929ad700f624", "children": ["4cb0939c-fe30-4e78-8121-d0cc302db99a"], "befores": [{"name": "driver", "status": "broken", "statusDetails": {"message": "selenium.common.exceptions.WebDriverException: Message: An unknown server-side error occurred while processing the command. Original error: The application at '/Users/hongxianyan/工作/workspace/myobservatory_app_automation/assets/myobservatory-5-12-1.apk' does not exist or is not accessible\nStacktrace:\nUnknownError: An unknown server-side error occurred while processing the command. Original error: The application at '/Users/hongxianyan/工作/workspace/myobservatory_app_automation/assets/myobservatory-5-12-1.apk' does not exist or is not accessible\n    at getResponseForW3CError (/usr/local/lib/node_modules/appium/node_modules/@appium/base-driver/lib/protocol/errors.js:1143:9)\n    at asyncHandler (/usr/local/lib/node_modules/appium/node_modules/@appium/base-driver/lib/protocol/protocol.js:487:57)\n", "trace": "  File \"/opt/anaconda3/lib/python3.9/site-packages/pluggy/callers.py\", line 187, in _multicall\n    res = hook_impl.function(*args)\n  File \"/opt/anaconda3/lib/python3.9/site-packages/_pytest/fixtures.py\", line 1123, in pytest_fixture_setup\n    result = call_fixture_func(fixturefunc, request, kwargs)\n  File \"/opt/anaconda3/lib/python3.9/site-packages/_pytest/fixtures.py\", line 895, in call_fixture_func\n    fixture_result = next(generator)\n  File \"/Users/hongxianyan/workspace/myobservatory_app_automation/conftest.py\", line 34, in driver\n    driver = get_driver(env, platform)\n  File \"/Users/hongxianyan/workspace/myobservatory_app_automation/utils/driver_manager.py\", line 27, in get_driver\n    return webdriver.Remote(\"http://localhost:4723\", options=UiAutomator2Options().load_capabilities(caps))\n  File \"/opt/anaconda3/lib/python3.9/site-packages/appium/webdriver/webdriver.py\", line 227, in __init__\n    super().__init__(\n  File \"/opt/anaconda3/lib/python3.9/site-packages/selenium/webdriver/remote/webdriver.py\", line 250, in __init__\n    self.start_session(capabilities)\n  File \"/opt/anaconda3/lib/python3.9/site-packages/appium/webdriver/webdriver.py\", line 319, in start_session\n    response = self.execute(RemoteCommand.NEW_SESSION, w3c_caps)\n  File \"/opt/anaconda3/lib/python3.9/site-packages/selenium/webdriver/remote/webdriver.py\", line 429, in execute\n    self.error_handler.check_response(response)\n  File \"/opt/anaconda3/lib/python3.9/site-packages/selenium/webdriver/remote/errorhandler.py\", line 232, in check_response\n    raise exception_class(message, screen, stacktrace)\n"}, "start": 1741518922801, "stop": 1741518923558}], "start": 1741518922801, "stop": 1741518923672}